Workbook

Sheet AQ At Risk GWh PAFA
A1: GWh | B1: Class 1 | C1: Class 2 | D1: Class 3 | E1: Class 4 >= 293,000 | F1: Class 4 Smart Monthly | G1: Class 4 Annual | H1: Total
A2: ACS | B2: - | C2: - | D2: - | E2: - | F2: 3 | G2: 1 | H2: =SUM(B2:G2) -> 4
A3: AGA | B3: 265 | C3: 22 | D3: 99 | E3: 5736 | F3: 5 | G3: 346 | H3: =SUM(B3:G3) -> 6473
A4: APE | B4: - | C4: - | D4: - | E4: - | F4: - | G4: 0 | H4: =SUM(B4:G4) -> 0
A5: BNG | B5: - | C5: - | D5: - | E5: 1 | F5: - | G5: 0 | H5: =SUM(B5:G5) -> 1
A6: BRK | B6: 0 | C6: 0 | D6: 3 | E6: 395 | F6: 0 | G6: 0 | H6: =SUM(B6:G6) -> 398
A7: BSH | B7: 0 | C7: - | D7: - | E7: 77 | F7: - | G7: 0 | H7: =SUM(B7:G7) -> 77
A8: BUE | B8: - | C8: - | D8: - | E8: 2 | F8: 0 | G8: 10 | H8: =SUM(B8:G8) -> 12
A9: BUS | B9: 0 | C9: 0 | D9: 50 | E9: 716 | F9: 20 | G9: 250 | H9: =SUM(B9:G9) -> 1036
A10: CGP | B10: - | C10: - | D10: 19 | E10: 242 | F10: 1 | G10: 18 | H10: =SUM(B10:G10) -> 280
A11: CIL | B11: - | C11: - | D11: - | E11: - | F11: 0 | G11: 0 | H11: =SUM(B11:G11) -> 0
A12: COU | B12: 0 | C12: - | D12: 0 | E12: - | F12: - | G12: - | H12: =SUM(B12:G12) -> 0
A13: CRE | B13: - | C13: - | D13: - | E13: - | F13: - | G13: 0 | H13: =SUM(B13:G13) -> 0
A14: DRA | B14: 0 | C14: - | D14: - | E14: - | F14: - | G14: - | H14: =SUM(B14:G14) -> 0
A15: DUA | B15: - | C15: - | D15: 2 | E15: 6 | F15: 2 | G15: 23 | H15: =SUM(B15:G15) -> 33
A16: ECG | B16: - | C16: - | D16: - | E16: 0 | F16: 1 | G16: 6 | H16: =SUM(B16:G16) -> 7
A17: EGD | B17: - | C17: - | D17: 0 | E17: - | F17: 6 | G17: 20 | H17: =SUM(B17:G17) -> 26
A18: EUK | B18: 313 | C18: 0 | D18: 0 | E18: 2 | F18: - | G18: 0 | H18: =SUM(B18:G18) -> 315
A19: FLX | B19: 0 | C19: 0 | D19: - | E19: 0 | F19: - | G19: - | H19: =SUM(B19:G19) -> 0
A20: FOX | B20: - | C20: - | D20: - | E20: 0 | F20: 37 | G20: 74 | H20: =SUM(B20:G20) -> 111
A21: FUE | B21: - | C21: - | D21: - | E21: 5 | F21: 964 | G21: 65 | H21: =SUM(B21:G21) -> 1034
A22: GGS | B22: - | C22: - | D22: - | E22: 0 | F22: 4 | G22: 4 | H22: =SUM(B22:G22) -> 8
A23: GLC | B23: 0 | C23: 0 | D23: 57 | E23: 2262 | F23: 17 | G23: 102 | H23: =SUM(B23:G23) -> 2438
A24: GRN | B24: - | C24: - | D24: - | E24: 1 | F24: 6 | G24: 11 | H24: =SUM(B24:G24) -> 18
A25: HBL | B25: - | C25: - | D25: - | E25: 0 | F25: 2 | G25: 6 | H25: =SUM(B25:G25) -> 8
A26: HEP | B26: 0 | C26: - | D26: 0 | E26: - | F26: - | G26: - | H26: =SUM(B26:G26) -> 0
A27: HET | B27: - | C27: - | D27: - | E27: 7 | F27: 6 | G27: 7 | H27: =SUM(B27:G27) -> 20
A28: HUD | B28: 0 | C28: 9 | D28: 12 | E28: 133 | F28: 3 | G28: 9 | H28: =SUM(B28:G28) -> 166
A29: IEO | B29: - | C29: - | D29: - | E29: - | F29: - | G29: 0 | H29: =SUM(B29:G29) -> 0
A30: KAL | B30: - | C30: - | D30: 6 | E30: 36 | F30: 12 | G30: 43 | H30: =SUM(B30:G30) -> 97
A31: LEP | B31: 0 | C31: - | D31: - | E31: 1 | F31: 0 | G31: 3 | H31: =SUM(B31:G31) -> 4
A32: MOG | B32: - | C32: - | D32: - | E32: 10 | F32: 1 | G32: 1 | H32: =SUM(B32:G32) -> 12
A33: MRB | B33: 0 | C33: - | D33: - | E33: 19 | F33: - | G33: 0 | H33: =SUM(B33:G33) -> 19
A34: NGD | B34: 28 | C34: 0 | D34: - | E34: 110 | F34: 0 | G34: 2 | H34: =SUM(B34:G34) -> 140
A35: NGS | B35: 0 | C35: 0 | D35: 174 | E35: 991 | F35: 5 | G35: 86 | H35: =SUM(B35:G35) -> 1256
A36: OCG | B36: - | C36: - | D36: 48 | E36: 87 | F36: 2528 | G36: 4046 | H36: =SUM(B36:G36) -> 6709
A37: OET | B37: - | C37: - | D37: 3 | E37: 54 | F37: 0 | G37: 10 | H37: =SUM(B37:G37) -> 67
A38: OSS | B38: - | C38: - | D38: 101 | E38: 1 | F38: 126 | G38: 299 | H38: =SUM(B38:G38) -> 527
A39: OVG | B39: - | C39: - | D39: 117 | E39: 4 | F39: 258 | G39: 1094 | H39: =SUM(B39:G39) -> 1473
A40: POW | B40: - | C40: - | D40: - | E40: 52 | F40: 1049 | G40: 1532 | H40: =SUM(B40:G40) -> 2633
...

Sheet Percentage Overdue PAFA
A1: Shipper | B1: Class 1 | C1: Class 2 | D1: Class 3 | E1: Class 4 >= 293,000 | F1: Class 4 Smart Monthly | G1: Class 4 Annual | H1: Total
A2: MOG | B2: - | C2: - | D2: - | E2: 0.26117 | F2: 0.08414 | G2: 0.01643 | H2: 0.10453
A3: BNG | B3: - | C3: - | D3: - | E3: 0.77582 | F3: - | G3: 0.07132 | H3: 0.19441
A4: CGP | B4: - | C4: - | D4: 0.00577 | E4: 0.24741 | F4: 0.08977 | G4: 0.04156 | H4: 0.06004
A5: DRA | B5: 0 | C5: - | D5: - | E5: - | F5: - | G5: - | H5: 0
A6: TRM | B6: - | C6: - | D6: 1 | E6: 0 | F6: 0.03609 | G6: 0.04838 | H6: 0.04695
A7: COU | B7: 0 | C7: - | D7: 0 | E7: - | F7: - | G7: - | H7: 0
A8: PZT | B8: 0 | C8: - | D8: - | E8: 0.32844 | F8: 0.14807 | G8: 0.04709 | H8: 0.17412
A9: IEO | B9: - | C9: - | D9: - | E9: - | F9: - | G9: 1 | H9: 1
A10: PSL | B10: 0 | C10: 0 | D10: - | E10: 0 | F10: - | G10: - | H10: 0
A11: OVG | B11: - | C11: - | D11: 0.0111 | E11: 0.31221 | F11: 0.06766 | G11: 0.11865 | H11: 0.0624
A12: SLD | B12: - | C12: - | D12: 0.04308 | E12: 0.12715 | F12: 0.08994 | G12: 0.10463 | H12: 0.09175
A13: BUS | B13: 0 | C13: 0 | D13: 0.01159 | E13: 0.27574 | F13: 0.07937 | G13: 0.06268 | H13: 0.07461
A14: WGS | B14: - | C14: - | D14: 0.00159 | E14: 0.5265 | F14: 0.33499 | G14: 0.26925 | H14: 0.04424
A15: SBP | B15: 0 | C15: - | D15: - | E15: 0.12191 | F15: - | G15: 0 | H15: 0.0935
A16: GGS | B16: - | C16: - | D16: - | E16: 0 | F16: 0.02059 | G16: 0.03239 | H16: 0.02517
A17: STL | B17: - | C17: - | D17: 0.03022 | E17: 0 | F17: 0.05698 | G17: 0.05901 | H17: 0.05713
A18: REG | B18: - | C18: - | D18: - | E18: 0.19665 | F18: 0.17041 | G18: 0.08319 | H18: 0.09343
A19: LEP | B19: 0 | C19: - | D19: - | E19: 1 | F19: 1 | G19: 0.91744 | H19: 0.94803
A20: TIL | B20: - | C20: - | D20: - | E20: 0.33242 | F20: 0.03969 | G20: 0.12454 | H20: 0.0792
A21: HET | B21: - | C21: - | D21: - | E21: 1 | F21: 0.05244 | G21: 0.07892 | H21: 0.09548
A22: APE | B22: - | C22: - | D22: - | E22: - | F22: - | G22: 1 | H22: 1
A23: NGS | B23: 0 | C23: 0 | D23: 0.0439 | E23: 0.08439 | F23: 0.11607 | G23: 0.0431 | H23: 0.03312
A24: REN | B24: - | C24: - | D24: - | E24: 0.11757 | F24: 0.02338 | G24: 0.07579 | H24: 0.06622
A25: QGM | B25: - | C25: - | D25: - | E25: 0 | F25: - | G25: 0.47046 | H25: 0.21171
A26: FLX | B26: 0 | C26: 0 | D26: - | E26: 0 | F26: - | G26: - | H26: 0
A27: EGD | B27: - | C27: - | D27: 6e-05 | E27: - | F27: 0.03487 | G27: 0.08242 | H27: 0.01984
A28: GRN | B28: - | C28: - | D28: - | E28: 0.30058 | F28: 0.19401 | G28: 0.3154 | H28: 0.25911
A29: HUD | B29: 0 | C29: 0.02099 | D29: 0.11678 | E29: 0.10148 | F29: 0.5819 | G29: 0.03915 | H29: 0.04965
A30: VEC | B30: 0 | C30: 0 | D30: 0.04146 | E30: 0.20345 | F30: 0.63647 | G30: 0.06951 | H30: 0.08623
A31: BRK | B31: 0 | C31: 0 | D31: 0.00642 | E31: 0.16415 | F31: 0.04581 | G31: 0.00507 | H31: 0.07124
A32: VAY | B32: - | C32: - | D32: - | E32: 1 | F32: - | G32: 1 | H32: 1
A33: BSH | B33: 0 | C33: - | D33: - | E33: 0.13098 | F33: - | G33: 0.71351 | H33: 0.07878
A34: DUA | B34: - | C34: - | D34: 0.01234 | E34: 0.29309 | F34: 0.09407 | G34: 0.07123 | H34: 0.06515
A35: KAL | B35: - | C35: - | D35: 0.01257 | E35: 0.1896 | F35: 0.08521 | G35: 0.07723 | H35: 0.07142
A36: HEP | B36: 0 | C36: - | D36: 0.0006 | E36: - | F36: - | G36: - | H36: 0.00053
A37: ACS | B37: - | C37: - | D37: - | E37: - | F37: 0.06824 | G37: 0.04033 | H37: 0.0566
A38: TRU | B38: - | C38: - | D38: - | E38: 0.54449 | F38: 0.09958 | G38: 0.29487 | H38: 0.18021
A39: SCP | B39: - | C39: - | D39: 0.04438 | E39: 0.1082 | F39: 0.24605 | G39: 0.07818 | H39: 0.0774
A40: GLC | B40: 0 | C40: 0 | D40: 0.01842 | E40: 0.24461 | F40: 0.19952 | G40: 0.08156 | H40: 0.12783
...
